<?xml version="1.0"?>
<mujoco model="g1 scene">
    <compiler angle="radian"/>

    <statistic center="0.3 0 0.4" extent="1.5"/>

    <visual>
        <headlight diffuse="0 0 0" ambient="1 1 1"/>
        <rgba fog="1.0 1.0 1.0 1.0"/>
        <global azimuth="120" elevation="-20"/>
    </visual>

    <asset>
        <material name="groundplane" rgba="0.9 0.9 0.9 1"/>
    </asset>

    <worldbody>
        <light pos="0 0 3" diffuse="1 1 1" castshadow="false" directional="true" intensity="2"/>
        <light pos="2 -3 3" dir="-2 3 -3" diffuse="1 1 1" directional="false" intensity="30"/>
        <geom name="floor" size="5 5 0.1" type="plane" material="groundplane"/>
        
        <body name="bed" pos=".5 .0 .0">
            <geom type="box" size=".3 .6 .65" rgba=".8 .8 .8 1" mass="0.1" friction="1 0.005 0.0001"/>
        </body>

        <body name="leg" pos=".4 -.3 .7">
            <geom type="capsule" size=".05" fromto="0 -.2 0  0 .1 0" rgba="1.0 .8 .8 1" mass="0.1"/>
            <body pos="0 .1 0">
                <joint name="hip" axis="1 0 0" frictionloss="1000" range="0 2"/>
                <geom type="capsule" size=".04" fromto="0 0 0  0 .28 0" rgba="1.0 .8 .8 1" mass="0.1"/>
                <site name="thigh_top" pos="0 0.14 0.04" quat="0 1 0 0"/>
                <geom type="cylinder" size=".005" fromto="0 0.14 0.041 0 0.14 0.039 " rgba=".0 .0 .8 1" mass="0"/>
                <site name="thigh_bottom" pos="0 0.14 -0.04" quat="1 0 0 0"/>
                <geom type="cylinder" size=".005" fromto="0 0.14 -0.041 0 0.14 -0.039 " rgba=".0 .0 .8 1" mass="0"/>
                <body pos="0 .28 0">
                    <joint name="knee" axis="1 0 0" frictionloss="1000" range="-2.5 0"/>
                    <geom type="capsule" size=".04" fromto="0 0 0  0 .28 0" rgba="1.0 .8 .8 1" mass="0.1"/>
                    <site name="calf_top" pos="0 0.14 0.04" quat="0 1 0 0"/>
                    <geom type="cylinder" size=".005" fromto="0 0.14 0.041 0 0.14 0.039 " rgba=".0 .0 .8 1" mass="0"/>
                    <site name="calf_bottom" pos="0 0.14 -0.04" quat="1 0 0 0"/>
                    <geom type="cylinder" size=".005" fromto="0 0.14 -0.041 0 0.14 -0.039 " rgba=".0 .0 .8 1" mass="0"/>
                    <body pos="0 .28 0">
                        <geom type="capsule" size=".035" fromto="0 0 0  0 0 0.1" rgba="1.0 .8 .8 1" mass="0.1"/>
                        <site name="foot_bottom" pos="0 0.035 0.05" quat="0.707 0.707 0 0"/>
                        <geom type="cylinder" size=".005" fromto="0 0.034 0.05 0 0.036 0.05 " rgba=".0 .0 .8 1" mass="0"/>
                    </body>
                </body>
            </body>
        </body>
    </worldbody>
</mujoco>
